<?xml version="1.0" encoding="UTF-8"?>
<!-- Generated by org.testng.reporters.JUnitReportReporter -->
<testsuite hostname="LAPTOP-I65AD951" failures="1" tests="6" name="test.retryAnalyzerDemo" time="0.019" errors="0" timestamp="2024-06-07T00:00:53 IST" skipped="3">
  <testcase classname="test.retryAnalyzerDemo" name="test3" time="0.002">
    <skipped/>
  </testcase> <!-- test3 -->
  <testcase classname="test.retryAnalyzerDemo" name="test3" time="0.001">
    <failure type="java.lang.AssertionError">
      <![CDATA[java.lang.AssertionError
at org.junit.Assert.fail(Assert.java:87)
at org.junit.Assert.assertTrue(Assert.java:42)
at org.junit.Assert.assertTrue(Assert.java:53)
at test.retryAnalyzerDemo.test3(retryAnalyzerDemo.java:25)
at java.base/jdk.internal.reflect.NativeMethodAccessorImpl.invoke0(Native Method)
at java.base/jdk.internal.reflect.NativeMethodAccessorImpl.invoke(NativeMethodAccessorImpl.java:77)
at java.base/jdk.internal.reflect.DelegatingMethodAccessorImpl.invoke(DelegatingMethodAccessorImpl.java:43)
at java.base/java.lang.reflect.Method.invoke(Method.java:568)
at org.testng.internal.invokers.MethodInvocationHelper.invokeMethod(MethodInvocationHelper.java:139)
at org.testng.internal.invokers.TestInvoker.invokeMethod(TestInvoker.java:664)
at org.testng.internal.invokers.TestInvoker.retryFailed(TestInvoker.java:249)
at org.testng.internal.invokers.MethodRunner.runInSequence(MethodRunner.java:76)
at org.testng.internal.invokers.TestInvoker$MethodInvocationAgent.invoke(TestInvoker.java:961)
at org.testng.internal.invokers.TestInvoker.invokeTestMethods(TestInvoker.java:201)
at org.testng.internal.invokers.TestMethodWorker.invokeTestMethods(TestMethodWorker.java:148)
at org.testng.internal.invokers.TestMethodWorker.run(TestMethodWorker.java:128)
at java.base/java.util.ArrayList.forEach(ArrayList.java:1511)
at org.testng.TestRunner.privateRun(TestRunner.java:819)
at org.testng.TestRunner.run(TestRunner.java:619)
at org.testng.SuiteRunner.runTest(SuiteRunner.java:443)
at org.testng.SuiteRunner.runSequentially(SuiteRunner.java:437)
at org.testng.SuiteRunner.privateRun(SuiteRunner.java:397)
at org.testng.SuiteRunner.run(SuiteRunner.java:336)
at org.testng.SuiteRunnerWorker.runSuite(SuiteRunnerWorker.java:52)
at org.testng.SuiteRunnerWorker.run(SuiteRunnerWorker.java:95)
at org.testng.TestNG.runSuitesSequentially(TestNG.java:1301)
at org.testng.TestNG.runSuitesLocally(TestNG.java:1228)
at org.testng.TestNG.runSuites(TestNG.java:1134)
at org.testng.TestNG.run(TestNG.java:1101)
at org.testng.remote.AbstractRemoteTestNG.run(AbstractRemoteTestNG.java:115)
at org.testng.remote.RemoteTestNG.initAndRun(RemoteTestNG.java:293)
at org.testng.remote.RemoteTestNG.main(RemoteTestNG.java:91)
]]>
    </failure>
  </testcase> <!-- test3 -->
  <testcase classname="test.retryAnalyzerDemo" name="test3" time="0.001">
    <skipped/>
  </testcase> <!-- test3 -->
  <testcase classname="test.retryAnalyzerDemo" name="test1" time="0.008"/>
  <testcase classname="test.retryAnalyzerDemo" name="test3" time="0.005">
    <skipped/>
  </testcase> <!-- test3 -->
  <testcase classname="test.retryAnalyzerDemo" name="test2" time="0.002"/>
</testsuite> <!-- test.retryAnalyzerDemo -->
